{"uuid": "c510b10a-c733-466f-b39c-7fa31d70cfef", "children": ["d59ca925-c8d2-4503-8061-ec64fc6464a5", "a5c67679-972a-4005-8cb1-56a8d8b5d8b6"], "befores": [{"name": "teardown", "status": "passed", "start": 1555620053951, "stop": 1555620053951}], "afters": [{"name": "teardown::fin", "status": "broken", "statusDetails": {"message": "urllib3.exceptions.MaxRetryError: HTTPConnectionPool(host='127.0.0.1', port=55410): Max retries exceeded with url: /session/81520b34-66bb-4db2-8c37-e9e9afd34cc3/elements (Caused by NewConnectionError('<urllib3.connection.HTTPConnection object at 0x04A1AA70>: Failed to establish a new connection: [WinError 10061] Подключение не установлено, т.к. конечный компьютер отверг запрос на подключение'))\n", "trace": "  File \"c:\\users\\ul1t0\\pycharmprojects\\python_b2\\env\\lib\\site-packages\\allure_commons\\_allure.py\", line 169, in __call__\n    return self._fixture_function(*args, **kwargs)\n  File \"C:\\Users\\ul1t0\\PycharmProjects\\python_B2\\conftest.py\", line 64, in fin\n    fixture.session.ensure_logout()\n  File \"C:\\Users\\ul1t0\\PycharmProjects\\python_B2\\fixture\\session.py\", line 23, in ensure_logout\n    if self.is_logged_in():\n  File \"C:\\Users\\ul1t0\\PycharmProjects\\python_B2\\fixture\\session.py\", line 36, in is_logged_in\n    return len(wd.find_elements_by_name(\"logout\")) > 0\n  File \"c:\\users\\ul1t0\\pycharmprojects\\python_b2\\env\\lib\\site-packages\\selenium\\webdriver\\remote\\webdriver.py\", line 512, in find_elements_by_name\n    return self.find_elements(by=By.NAME, value=name)\n  File \"c:\\users\\ul1t0\\pycharmprojects\\python_b2\\env\\lib\\site-packages\\selenium\\webdriver\\remote\\webdriver.py\", line 1007, in find_elements\n    'value': value})['value'] or []\n  File \"c:\\users\\ul1t0\\pycharmprojects\\python_b2\\env\\lib\\site-packages\\selenium\\webdriver\\remote\\webdriver.py\", line 319, in execute\n    response = self.command_executor.execute(driver_command, params)\n  File \"c:\\users\\ul1t0\\pycharmprojects\\python_b2\\env\\lib\\site-packages\\selenium\\webdriver\\remote\\remote_connection.py\", line 374, in execute\n    return self._request(command_info[0], url, body=data)\n  File \"c:\\users\\ul1t0\\pycharmprojects\\python_b2\\env\\lib\\site-packages\\selenium\\webdriver\\remote\\remote_connection.py\", line 397, in _request\n    resp = self._conn.request(method, url, body=body, headers=headers)\n  File \"c:\\users\\ul1t0\\pycharmprojects\\python_b2\\env\\lib\\site-packages\\urllib3\\request.py\", line 72, in request\n    **urlopen_kw)\n  File \"c:\\users\\ul1t0\\pycharmprojects\\python_b2\\env\\lib\\site-packages\\urllib3\\request.py\", line 150, in request_encode_body\n    return self.urlopen(method, url, **extra_kw)\n  File \"c:\\users\\ul1t0\\pycharmprojects\\python_b2\\env\\lib\\site-packages\\urllib3\\poolmanager.py\", line 323, in urlopen\n    response = conn.urlopen(method, u.request_uri, **kw)\n  File \"c:\\users\\ul1t0\\pycharmprojects\\python_b2\\env\\lib\\site-packages\\urllib3\\connectionpool.py\", line 667, in urlopen\n    **response_kw)\n  File \"c:\\users\\ul1t0\\pycharmprojects\\python_b2\\env\\lib\\site-packages\\urllib3\\connectionpool.py\", line 667, in urlopen\n    **response_kw)\n  File \"c:\\users\\ul1t0\\pycharmprojects\\python_b2\\env\\lib\\site-packages\\urllib3\\connectionpool.py\", line 667, in urlopen\n    **response_kw)\n  File \"c:\\users\\ul1t0\\pycharmprojects\\python_b2\\env\\lib\\site-packages\\urllib3\\connectionpool.py\", line 638, in urlopen\n    _stacktrace=sys.exc_info()[2])\n  File \"c:\\users\\ul1t0\\pycharmprojects\\python_b2\\env\\lib\\site-packages\\urllib3\\util\\retry.py\", line 398, in increment\n    raise MaxRetryError(_pool, url, error or ResponseError(cause))\n"}, "start": 1555620085713, "stop": 1555620089750}], "start": 1555620053951, "stop": 1555620089750}